2024-11-20 22:31:58,631 - INFO - Training configuration:
2024-11-20 22:31:58,632 - INFO - num_points: 4096
2024-11-20 22:31:58,633 - INFO - chunk_size: 4096
2024-11-20 22:31:58,633 - INFO - overlap: 2048
2024-11-20 22:31:58,634 - INFO - batch_size: 48
2024-11-20 22:31:58,635 - INFO - num_workers: 2
2024-11-20 22:31:58,635 - INFO - learning_rate: 0.001
2024-11-20 22:31:58,636 - INFO - num_classes: 5
2024-11-20 22:31:58,637 - INFO - num_epochs: 500
2024-11-20 22:31:58,638 - INFO - device: cuda
2024-11-20 22:31:58,639 - INFO - Using device: cuda
2024-11-20 22:31:58,641 - INFO - 开始预加载数据到内存...
2024-11-20 22:33:02,940 - INFO - 数据预加载完成，共 85264 个数据块
2024-11-20 22:33:02,946 - INFO - 有效标签: [0, 1, 2, 3, 4]
2024-11-20 22:33:02,954 - INFO - reading train data
2024-11-20 22:33:02,961 - INFO - 开始预加载数据到内存...
2024-11-20 22:33:11,708 - INFO - 数据预加载完成，共 4729 个数据块
2024-11-20 22:33:11,711 - INFO - 有效标签: [0, 1, 2, 3, 4]
2024-11-20 22:33:11,913 - INFO - 验证集创建完成，使用 945 个数据块 (总共 4729 个的 20.0%)
2024-11-20 22:33:11,914 - INFO - 有效标签: [0, 1, 2, 3, 4]
2024-11-20 22:33:11,919 - INFO - reading val data
2024-11-20 22:33:44,791 - INFO - Train dataset size: 85264
2024-11-20 22:33:44,792 - INFO - Val dataset size: 945
2024-11-20 22:34:00,130 - ERROR - Training failed with exception:
Traceback (most recent call last):
  File "C:\Users\Administrator\AppData\Local\Temp\ipykernel_26492\2528016048.py", line 230, in <module>
    train()
  File "C:\Users\Administrator\AppData\Local\Temp\ipykernel_26492\2528016048.py", line 5, in train
    model = EnhancedPointNet2(num_classes).to(device)
            ^^^^^^^^^^^^^^^^^
NameError: name 'EnhancedPointNet2' is not defined
