2024-11-21 18:42:26,154 - INFO - Training configuration:
2024-11-21 18:42:26,154 - INFO - num_points: 4096
2024-11-21 18:42:26,154 - INFO - chunk_size: 4096
2024-11-21 18:42:26,154 - INFO - overlap: 1024
2024-11-21 18:42:26,154 - INFO - batch_size: 64
2024-11-21 18:42:26,154 - INFO - num_workers: 0
2024-11-21 18:42:26,154 - INFO - learning_rate: 0.001
2024-11-21 18:42:26,154 - INFO - num_classes: 5
2024-11-21 18:42:26,154 - INFO - num_epochs: 500
2024-11-21 18:42:26,154 - INFO - device: cuda
2024-11-21 18:42:26,155 - INFO - Using device: cuda
2024-11-21 18:42:26,155 - ERROR - Training failed with exception:
Traceback (most recent call last):
  File "D:\Work\Pointcloud-WL\Pointcloud-bridge\Highway_bridge\train.py", line 320, in <module>
    train()
  File "D:\Work\Pointcloud-WL\Pointcloud-bridge\Highway_bridge\train.py", line 55, in train
    train_dataset = BridgePointCloudDataset(
                    ^^^^^^^^^^^^^^^^^^^^^^^^
  File "D:\Work\Pointcloud-WL\Pointcloud-bridge\Highway_bridge\utils\data_utils.py", line 60, in __init__
    self.file_list = sorted([f for f in os.listdir(data_folder)
                                        ^^^^^^^^^^^^^^^^^^^^^^^
FileNotFoundError: [WinError 3] 指定されたパスが見つかりません。: 'data/fukushima/onepart/train/train'
