2024-11-21 18:59:58,884 - INFO - Training configuration:
2024-11-21 18:59:58,884 - INFO - num_points: 4096
2024-11-21 18:59:58,884 - INFO - chunk_size: 4096
2024-11-21 18:59:58,884 - INFO - overlap: 1024
2024-11-21 18:59:58,884 - INFO - batch_size: 64
2024-11-21 18:59:58,884 - INFO - num_workers: 0
2024-11-21 18:59:58,884 - INFO - learning_rate: 0.001
2024-11-21 18:59:58,884 - INFO - num_classes: 5
2024-11-21 18:59:58,884 - INFO - num_epochs: 500
2024-11-21 18:59:58,884 - INFO - device: cuda
2024-11-21 18:59:58,884 - INFO - Using device: cuda
2024-11-21 18:59:58,884 - INFO - Loading train data...
2024-11-21 19:00:05,365 - INFO - reading train data
2024-11-21 19:00:05,365 - INFO - Loading val data...
2024-11-21 19:00:06,447 - INFO - reading val data
2024-11-21 19:00:06,448 - INFO - Train dataset size: 6
2024-11-21 19:00:06,448 - INFO - Val dataset size: 1
2024-11-21 19:00:07,235 - INFO - Total samples is: <torch.utils.data.dataloader.DataLoader object at 0x0000023287D09EE0>
2024-11-21 19:00:07,744 - ERROR - Training failed with exception:
Traceback (most recent call last):
  File "D:\Work\Pointcloud-WL\Pointcloud-bridge\Highway_bridge\train.py", line 320, in <module>
    train()
  File "D:\Work\Pointcloud-WL\Pointcloud-bridge\Highway_bridge\train.py", line 139, in train
    outputs = model(points, colors)
              ^^^^^^^^^^^^^^^^^^^^^
  File "C:\Users\cy519\anaconda3\envs\pytorch\Lib\site-packages\torch\nn\modules\module.py", line 1736, in _wrapped_call_impl
    return self._call_impl(*args, **kwargs)
           ^^^^^^^^^^^^^^^^^^^^^^^^^^^^^^^^
  File "C:\Users\cy519\anaconda3\envs\pytorch\Lib\site-packages\torch\nn\modules\module.py", line 1747, in _call_impl
    return forward_call(*args, **kwargs)
           ^^^^^^^^^^^^^^^^^^^^^^^^^^^^^
  File "D:\Work\Pointcloud-WL\Pointcloud-bridge\Highway_bridge\models\model.py", line 38, in forward
    l1_xyz, l1_points = self.sa1(xyz, points)
                        ^^^^^^^^^^^^^^^^^^^^^
  File "C:\Users\cy519\anaconda3\envs\pytorch\Lib\site-packages\torch\nn\modules\module.py", line 1736, in _wrapped_call_impl
    return self._call_impl(*args, **kwargs)
           ^^^^^^^^^^^^^^^^^^^^^^^^^^^^^^^^
  File "C:\Users\cy519\anaconda3\envs\pytorch\Lib\site-packages\torch\nn\modules\module.py", line 1747, in _call_impl
    return forward_call(*args, **kwargs)
           ^^^^^^^^^^^^^^^^^^^^^^^^^^^^^
  File "D:\Work\Pointcloud-WL\Pointcloud-bridge\Highway_bridge\models\pointnet2_utils.py", line 122, in forward
    new_xyz, new_points = sample_and_group(self.npoint, self.radius, self.nsample, xyz, points)
                          ^^^^^^^^^^^^^^^^^^^^^^^^^^^^^^^^^^^^^^^^^^^^^^^^^^^^^^^^^^^^^^^^^^^^^
  File "D:\Work\Pointcloud-WL\Pointcloud-bridge\Highway_bridge\models\pointnet2_utils.py", line 44, in sample_and_group
    fps_idx = farthest_point_sample(xyz, npoint)
              ^^^^^^^^^^^^^^^^^^^^^^^^^^^^^^^^^^
  File "D:\Work\Pointcloud-WL\Pointcloud-bridge\Highway_bridge\models\pointnet2_utils.py", line 73, in farthest_point_sample
    distance[mask] = dist[mask]
    ~~~~~~~~^^^^^^
RuntimeError: Index put requires the source and destination dtypes match, got Float for the destination and Double for the source.
