2024-11-22 20:04:48,598 - INFO - Training configuration:
2024-11-22 20:04:48,599 - INFO - num_points: 4096
2024-11-22 20:04:48,599 - INFO - chunk_size: 4096
2024-11-22 20:04:48,599 - INFO - overlap: 1024
2024-11-22 20:04:48,599 - INFO - batch_size: 64
2024-11-22 20:04:48,599 - INFO - num_workers: 0
2024-11-22 20:04:48,599 - INFO - learning_rate: 0.001
2024-11-22 20:04:48,599 - INFO - num_classes: 5
2024-11-22 20:04:48,599 - INFO - num_epochs: 500
2024-11-22 20:04:48,599 - INFO - device: cuda
2024-11-22 20:04:48,599 - INFO - Using device: cuda
2024-11-22 20:04:48,599 - ERROR - Training failed with exception:
Traceback (most recent call last):
  File "D:\Work\Pointcloud-WL\Pointcloud-bridge\Highway_bridge\train.py", line 326, in <module>
    train()
  File "D:\Work\Pointcloud-WL\Pointcloud-bridge\Highway_bridge\train.py", line 55, in train
    train_dataset = BridgePointCloudDataset(
                    ^^^^^^^^^^^^^^^^^^^^^^^^
  File "D:\Work\Pointcloud-WL\Pointcloud-bridge\Highway_bridge\utils\BridgePCDataset.py", line 40, in __init__
    self.logger = get_logger()
                  ^^^^^^^^^^
NameError: name 'get_logger' is not defined
